 * Serving Flask app "app"
 * Forcing debug mode on
Traceback (most recent call last):
  File "/usr/local/bin/flask", line 11, in <module>
    sys.exit(main())
  File "/usr/local/lib64/python3.6/site-packages/flask/cli.py", line 478, in main
    cli.main(args=args, prog_name=name)
  File "/usr/local/lib64/python3.6/site-packages/flask/cli.py", line 345, in main
    return AppGroup.main(self, *args, **kwargs)
  File "/usr/local/lib/python3.6/site-packages/click/core.py", line 697, in main
    rv = self.invoke(ctx)
  File "/usr/local/lib/python3.6/site-packages/click/core.py", line 1066, in invoke
    return _process_result(sub_ctx.command.invoke(sub_ctx))
  File "/usr/local/lib/python3.6/site-packages/click/core.py", line 895, in invoke
    return ctx.invoke(self.callback, **ctx.params)
  File "/usr/local/lib/python3.6/site-packages/click/core.py", line 535, in invoke
    return callback(*args, **kwargs)
  File "/usr/local/lib/python3.6/site-packages/click/decorators.py", line 64, in new_func
    return ctx.invoke(f, obj, *args[1:], **kwargs)
  File "/usr/local/lib/python3.6/site-packages/click/core.py", line 535, in invoke
    return callback(*args, **kwargs)
  File "/usr/local/lib64/python3.6/site-packages/flask/cli.py", line 403, in run_command
    use_debugger=debugger, threaded=with_threads)
  File "/usr/local/lib/python3.6/site-packages/werkzeug/serving.py", line 795, in run_simple
    s.bind(get_sockaddr(hostname, port, address_family))
OSError: [Errno 98] Address already in use
